Workbook

Sheet Bedarf
A1: Notfallvorrat: Bedarf pro Person
A2: Gelbe Felder sind Eingaben. Alle anderen Werte werden berechnet.
A3: Eingabe | B3: Wert | C3: Einheit
A4: Körpergewicht | B4: 97.5 | C4: kg
A5: Aktivitätsfaktor (Krise) | B5: 1.3 | C5: x
A6: Energiebedarf je kg Körpergewicht | B6: 24 | C6: kcal/kg/Tag
A7: Trinkwasser je kg Körpergewicht | B7: 35 | C7: ml/kg/Tag
A8: Hygienewasser | B8: 2 | C8: L/Tag
A9: Zeitraum | B9: 10 | C9: Tage
A11: Ergebnis | B11: Wert | C11: Einheit
A12: Energiebedarf | B12: =B4*B6*B5 | C12: kcal/Tag
A13: Trinkwasser | B13: =B4*B7/1000 | C13: L/Tag
A14: Trinkwasser für den Zeitraum | B14: =B13*B9 | C14: L
A15: Wasser inkl. Hygiene für den Zeitraum | B15: =B14+B8*B9 | C15: L
A16: Lebensmittel für den Zeitraum (ohne Haushaltsfaktor) | B16: =B12/2000*Lebensmittel!D13*B9/10 | C16: kg
A17: Lebensmittel-Energie im Vorrat für den Zeitraum | B17: =Lebensmittel!E13*B9/10 | C17: kcal
A18: Deckungsgrad des Lebensmittelvorrats | B18: =B17/(B12*B9) | C18: %
A20: Vergleich nach Körpergewicht (Zeitraum laut Eingabe)
A21: Körpergewicht (kg) | B21: kcal/Tag | C21: Trinkwasser (L/Tag) | D21: Wasser inkl. Hygiene (L)
A22: 65 | B22: =A22*$B$6*$B$5 | C22: =A22*$B$7/1000 | D22: =A22*$B$7/1000*$B$9+$B$8*$B$9
A23: 97.5 | B23: =A23*$B$6*$B$5 | C23: =A23*$B$7/1000 | D23: =A23*$B$7/1000*$B$9+$B$8*$B$9
A24: 130 | B24: =A24*$B$6*$B$5 | C24: =A24*$B$7/1000 | D24: =A24*$B$7/1000*$B$9+$B$8*$B$9

Sheet Haushalt
A1: Haushaltsrechner: Vorrat für mehrere Personen
A2: Gewicht jeder Person eintragen (gelbe Felder). Zeitraum kommt aus Bedarf!B9.
A3: Zeitraum (Tage) | B3: =Bedarf!B9
A4: Anzahl Personen | B4: =COUNT(B7:B14)
A6: Name | B6: Gewicht (kg) | C6: kcal pro Tag | D6: Lebensmittel-Faktor | E6: Lebensmittel (kg) | F6: Trinkwasser (L) | G6: Hygienewasser (L) | H6: Wasser gesamt (L)
A7: Person 1 | B7: 97.5 | C7: =IF(B7="","",B7*Bedarf!$B$6*Bedarf!$B$5) | D7: =IF(B7="","",C7/2000) | E7: =IF(B7="","",D7*Lebensmittel!$D$13*$B$3/10) | F7: =IF(B7="","",B7*Bedarf!$B$7/1000*$B$3) | G7: =IF(B7="","",Bedarf!$B$8*$B$3) | H7: =IF(B7="","",F7+G7)
A8: Person 2 | B8: 65 | C8: =IF(B8="","",B8*Bedarf!$B$6*Bedarf!$B$5) | D8: =IF(B8="","",C8/2000) | E8: =IF(B8="","",D8*Lebensmittel!$D$13*$B$3/10) | F8: =IF(B8="","",B8*Bedarf!$B$7/1000*$B$3) | G8: =IF(B8="","",Bedarf!$B$8*$B$3) | H8: =IF(B8="","",F8+G8)
A9: Person 3 | B9: 130 | C9: =IF(B9="","",B9*Bedarf!$B$6*Bedarf!$B$5) | D9: =IF(B9="","",C9/2000) | E9: =IF(B9="","",D9*Lebensmittel!$D$13*$B$3/10) | F9: =IF(B9="","",B9*Bedarf!$B$7/1000*$B$3) | G9: =IF(B9="","",Bedarf!$B$8*$B$3) | H9: =IF(B9="","",F9+G9)
C10: =IF(B10="","",B10*Bedarf!$B$6*Bedarf!$B$5) | D10: =IF(B10="","",C10/2000) | E10: =IF(B10="","",D10*Lebensmittel!$D$13*$B$3/10) | F10: =IF(B10="","",B10*Bedarf!$B$7/1000*$B$3) | G10: =IF(B10="","",Bedarf!$B$8*$B$3) | H10: =IF(B10="","",F10+G10)
C11: =IF(B11="","",B11*Bedarf!$B$6*Bedarf!$B$5) | D11: =IF(B11="","",C11/2000) | E11: =IF(B11="","",D11*Lebensmittel!$D$13*$B$3/10) | F11: =IF(B11="","",B11*Bedarf!$B$7/1000*$B$3) | G11: =IF(B11="","",Bedarf!$B$8*$B$3) | H11: =IF(B11="","",F11+G11)
C12: =IF(B12="","",B12*Bedarf!$B$6*Bedarf!$B$5) | D12: =IF(B12="","",C12/2000) | E12: =IF(B12="","",D12*Lebensmittel!$D$13*$B$3/10) | F12: =IF(B12="","",B12*Bedarf!$B$7/1000*$B$3) | G12: =IF(B12="","",Bedarf!$B$8*$B$3) | H12: =IF(B12="","",F12+G12)
C13: =IF(B13="","",B13*Bedarf!$B$6*Bedarf!$B$5) | D13: =IF(B13="","",C13/2000) | E13: =IF(B13="","",D13*Lebensmittel!$D$13*$B$3/10) | F13: =IF(B13="","",B13*Bedarf!$B$7/1000*$B$3) | G13: =IF(B13="","",Bedarf!$B$8*$B$3) | H13: =IF(B13="","",F13+G13)
C14: =IF(B14="","",B14*Bedarf!$B$6*Bedarf!$B$5) | D14: =IF(B14="","",C14/2000) | E14: =IF(B14="","",D14*Lebensmittel!$D$13*$B$3/10) | F14: =IF(B14="","",B14*Bedarf!$B$7/1000*$B$3) | G14: =IF(B14="","",Bedarf!$B$8*$B$3) | H14: =IF(B14="","",F14+G14)
A15: Summe | C15: =SUM(C7:C14) | D15: =SUM(D7:D14) | E15: =SUM(E7:E14) | F15: =SUM(F7:F14) | G15: =SUM(G7:G14) | H15: =SUM(H7:H14)
A17: Hinweis: Die Lebensmittelmenge pro Person skaliert mit dem Energiebedarf (Faktor = kcal pro Tag / 2.000).
A18: Trinkwasser: BBK-Richtwert wird über den Körpergewichtsansatz berechnet. Hygienewasser kommt zusätzlich dazu.

Sheet Lebensmittel
A1: Lebensmittelvorrat (Basis: 2.000 kcal pro Person und Tag, 10 Tage)
A2: Für Personen mit mehr Energiebedarf skaliert der Haushaltsrechner die Mengen automatisch.
A4: Lebensmittel | B4: Menge | C4: Einheit | D4: ca. kg | E4: ca. kcal | F4: Anmerkung
A5: Reis, Nudeln, Haferflocken | B5: 1.8 | C5: kg | D5: 1.8 | E5: 6300 | F5: Grundnahrung, lange haltbar
A6: Hülsenfrüchte (Linsen, Bohnen) | B6: 0.7 | C6: kg | D6: 0.7 | E6: 2400 | F6: Eiweiß
A7: Konserven (Gemüse, Fisch, Fleisch) | B7: 2.5 | C7: kg | D7: 2.5 | E7: 2500 | F7: Mit Dosenöffner
A8: Speiseöl | B8: 0.35 | C8: L | D8: 0.32 | E8: 3080 | F8: Energiedichte
A9: Zucker oder Honig | B9: 0.3 | C9: kg | D9: 0.3 | E9: 1200 | F9: Schnelle Energie
A10: Nüsse, Müsli, Trockenfrüchte | B10: 0.3 | C10: kg | D10: 0.3 | E10: 1350 | F10: Snacks
A11: H-Milch oder Milchpulver | B11: 2 | C11: L | D11: 2.06 | E11: 1300 | F11: Auch zum Kochen
A12: Knäckebrot oder Zwieback | B12: 0.5 | C12: kg | D12: 0.5 | E12: 1750 | F12: Brot-Ersatz
A13: Summe | D13: =SUM(D5:D12) | E13: =SUM(E5:E12)
A14: kcal pro Tag | E14: =E13/10

Sheet Ausruestung
A1: Ausrüstung und Haushaltsvorrat
A2: Gesamt = pro Person × Anzahl Personen (Haushalt!B4) + pro Haushalt. Die Anzahl Personen wird automatisch übernommen.
A4: Kategorie | B4: Artikel | C4: Pro Person | D4: Pro Haushalt | E4: Einheit | F4: Gesamt | G4: Hinweis | H4: Erledigt
A5: Wasser-Technik | B5: Trinkwasser-Kanister (10 L) | C5: 0 | D5: 2 | E5: Stück | F5: =C5*Haushalt!$B$4+D5 | G5: Wasser getrennt lagern, Ablaufdatum beachten
A6: Wasser-Technik | B6: Wasserfilter | C6: 0 | D6: 1 | E6: Stück | F6: =C6*Haushalt!$B$4+D6 | G6: Für Oberflächen- oder Leitungswasser
A7: Wasser-Technik | B7: Entkeimungstabletten | C7: 0 | D7: 1 | E7: Packung | F7: =C7*Haushalt!$B$4+D7 | G7: Nach Packungsanleitung
A8: Licht und Strom | B8: Kurbel-Taschenlampe (Aufzieher) | C8: 1 | D8: 0 | E8: Stück | F8: =C8*Haushalt!$B$4+D8 | G8: Funktioniert ohne Batterien
A9: Licht und Strom | B9: Stirnlampe | C9: 1 | D9: 0 | E9: Stück | F9: =C9*Haushalt!$B$4+D9 | G9: Hände bleiben frei
A10: Licht und Strom | B10: Kurbelradio mit USB-Anschluss | C10: 0 | D10: 1 | E10: Stück | F10: =C10*Haushalt!$B$4+D10 | G10: Empfang von Warnmeldungen
A11: Licht und Strom | B11: Solar-Ladegerät (faltbar, USB) | C11: 0 | D11: 1 | E11: Stück | F11: =C11*Haushalt!$B$4+D11 | G11: Nur bei Sonne, lädt langsam
A12: Licht und Strom | B12: Powerbank (mind. 10.000 mAh) | C12: 1 | D12: 0 | E12: Stück | F12: =C12*Haushalt!$B$4+D12 | G12: Vorher voll laden
A13: Licht und Strom | B13: Batterien AA | C13: 0 | D13: 24 | E13: Stück | F13: =C13*Haushalt!$B$4+D13 | G13: Für Radio und Lampen
A14: Licht und Strom | B14: Batterien AAA | C14: 0 | D14: 12 | E14: Stück | F14: =C14*Haushalt!$B$4+D14 | G14: Für Stirnlampen und Kleingeräte
A15: Kochen und Wärme | B15: Gaskocher | C15: 0 | D15: 1 | E15: Stück | F15: =C15*Haushalt!$B$4+D15 | G15: Nur im Freien oder gut belüftet
A16: Kochen und Wärme | B16: Gaskartuschen | C16: 0 | D16: 6 | E16: Stück | F16: =C16*Haushalt!$B$4+D16 | G16: Ersatz für den Gaskocher
... A18: Kochen und Wärme | B18: Trockenbrennstoff-Würfel | C18: 20 | D18: 0 | E18: Stück | F18: =C18*Haushalt!$B$4+D18 | G18: ca. 2 Würfel pro Mahlzeit
A19: Kochen und Wärme | B19: Kochtopf, Geschirr und Besteck | C19: 1 | D19: 0 | E19: Satz | F19: =C19*Haushalt!$B$4+D19
A20: Kochen und Wärme | B20: Dosenöffner (manuell) | C20: 0 | D20: 1 | E20: Stück | F20: =C20*Haushalt!$B$4+D20 | G20: Für Konserven
A21: Kochen und Wärme | B21: Feuerzeug | C21: 0 | D21: 2 | E21: Stück | F21: =C21*Haushalt!$B$4+D21
A22: Kochen und Wärme | B22: Wasserfeste Streichhölzer | C22: 0 | D22: 2 | E22: Packung | F22: =C22*Haushalt!$B$4+D22
A23: Kochen und Wärme | B23: Kerzen | C23: 0 | D23: 10 | E23: Stück | F23: =C23*Haushalt!$B$4+D23 | G23: Brandgefahr, nie unbeaufsichtigt
A24: Kochen und Wärme | B24: Schlafsack oder Decke | C24: 1 | D24: 0 | E24: Stück | F24: =C24*Haushalt!$B$4+D24
A25: Kochen und Wärme | B25: Warme Kleidung und feste Schuhe | C25: 1 | D25: 0 | E25: Satz | F25: =C25*Haushalt!$B$4+D25 | G25: Zusätzlich zur Alltagskleidung
A26: Kochen und Wärme | B26: Regenschutz | C26: 1 | D26: 0 | E26: Stück | F26: =C26*Haushalt!$B$4+D26
A27: Sicherheit | B27: CO-Melder | C27: 0 | D27: 1 | E27: Stück | F27: =C27*Haushalt!$B$4+D27 | G27: Warnt vor Kohlenmonoxid
A28: Sicherheit | B28: Rauchmelder | C28: 0 | D28: 1 | E28: Stück | F28: =C28*Haushalt!$B$4+D28 | G28: Pflicht in vielen Wohnungen
A29: Sicherheit | B29: Feuerlöscher | C29: 0 | D29: 1 | E29: Stück | F29: =C29*Haushalt!$B$4+D29
A30: Sicherheit | B30: Notfalltasche (Rucksack) | C30: 1 | D30: 0 | E30: Stück | F30: =C30*Haushalt!$B$4+D30 | G30: Griffbereit, mit Dokumentenkopien
A31: Wasser-Technik | B31: Multitool | C31: 0 | D31: 1 | E31: Stück | F31: =C31*Haushalt!$B$4+D31
A32: Wasser-Technik | B32: Klebeband (Rolle) und Schere | C32: 0 | D32: 1 | E32: Satz | F32: =C32*Haushalt!$B$4+D32
A33: Wasser-Technik | B33: Müllbeutel | C33: 0 | D33: 20 | E33: Stück | F33: =C33*Haushalt!$B$4+D33
A34: Wasser-Technik | B34: Handschuhe | C34: 0 | D34: 4 | E34: Paar | F34: =C34*Haushalt!$B$4+D34
A35: Wasser-Technik | B35: FFP2-Masken | C35: 10 | D35: 0 | E35: Stück | F35: =C35*Haushalt!$B$4+D35
A36: Wasser-Technik | B36: Kompass und Karte | C36: 0 | D36: 1 | E36: Satz | F36: =C36*Haushalt!$B$4+D36 | G36: Falls GPS ausfällt
A37: Wasser-Technik | B37: Haustierfutter | C37: 0 | D37: 0 | E37: nach Bedarf | F37: =C37*Haushalt!$B$4+D37 | G37: Nur bei Haustieren, Menge selbst eintragen
A38: Gesundheit und Hygiene | B38: Erste-Hilfe-Set (DIN 13157) | C38: 0 | D38: 1 | E38: Stück | F38: =C38*Haushalt!$B$4+D38
A39: Gesundheit und Hygiene | B39: Medikamente (14 Tage Vorrat) | C39: 1 | D39: 0 | E39: Satz | F39: =C39*Haushalt!$B$4+D39 | G39: Ärztliche Rücksprache
A40: Gesundheit und Hygiene | B40: Hygieneartikel (Seife, Zahnpflege, Feuchttücher) | C40: 1 | D40: 0 | E40: Satz | F40: =C40*Haushalt!$B$4+D40
A41: Gesundheit und Hygiene | B41: Toilettenpapier | C41: 8 | D41: 0 | E41: Rolle | F41: =C41*Haushalt!$B$4+D41
A42: Gesundheit und Hygiene | B42: Desinfektionsmittel | C42: 0 | D42: 1 | E42: Flasche | F42: =C42*Haushalt!$B$4+D42
...

Sheet Einkaufsliste
A1: Einkaufsliste mit Kosten
A2: Preis je Einheit eintragen (gelbe Felder). Die Summe wird automatisch berechnet.
A4: Artikel | B4: Menge | C4: Einheit | D4: Preis je Einheit (€) | E4: Summe (€) | F4: Erledigt
A5: Reis, Nudeln, Haferflocken | B5: =Lebensmittel!B5*SUM(Haushalt!$D$7:$D$14)*Haushalt!$B$3/10 | C5: kg | E5: =IF(D5="","",B5*D5)
A6: Hülsenfrüchte (Linsen, Bohnen) | B6: =Lebensmittel!B6*SUM(Haushalt!$D$7:$D$14)*Haushalt!$B$3/10 | C6: kg | E6: =IF(D6="","",B6*D6)
A7: Konserven (Gemüse, Fisch, Fleisch) | B7: =Lebensmittel!B7*SUM(Haushalt!$D$7:$D$14)*Haushalt!$B$3/10 | C7: kg | E7: =IF(D7="","",B7*D7)
A8: Speiseöl | B8: =Lebensmittel!B8*SUM(Haushalt!$D$7:$D$14)*Haushalt!$B$3/10 | C8: L | E8: =IF(D8="","",B8*D8)
A9: Zucker oder Honig | B9: =Lebensmittel!B9*SUM(Haushalt!$D$7:$D$14)*Haushalt!$B$3/10 | C9: kg | E9: =IF(D9="","",B9*D9)
A10: Nüsse, Müsli, Trockenfrüchte | B10: =Lebensmittel!B10*SUM(Haushalt!$D$7:$D$14)*Haushalt!$B$3/10 | C10: kg | E10: =IF(D10="","",B10*D10)
A11: H-Milch oder Milchpulver | B11: =Lebensmittel!B11*SUM(Haushalt!$D$7:$D$14)*Haushalt!$B$3/10 | C11: L | E11: =IF(D11="","",B11*D11)
A12: Knäckebrot oder Zwieback | B12: =Lebensmittel!B12*SUM(Haushalt!$D$7:$D$14)*Haushalt!$B$3/10 | C12: kg | E12: =IF(D12="","",B12*D12)
A13: =Ausruestung!B5 | B13: =Ausruestung!F5 | C13: =Ausruestung!E5 | E13: =IF(D13="","",B13*D13)
A14: =Ausruestung!B6 | B14: =Ausruestung!F6 | C14: =Ausruestung!E6 | E14: =IF(D14="","",B14*D14)
A15: =Ausruestung!B7 | B15: =Ausruestung!F7 | C15: =Ausruestung!E7 | E15: =IF(D15="","",B15*D15)
A16: =Ausruestung!B8 | B16: =Ausruestung!F8 | C16: =Ausruestung!E8 | E16: =IF(D16="","",B16*D16)
A17: =Ausruestung!B9 | B17: =Ausruestung!F9 | C17: =Ausruestung!E9 | E17: =IF(D17="","",B17*D17)
A18: =Ausruestung!B10 | B18: =Ausruestung!F10 | C18: =Ausruestung!E10 | E18: =IF(D18="","",B18*D18)
A19: =Ausruestung!B11 | B19: =Ausruestung!F11 | C19: =Ausruestung!E11 | E19: =IF(D19="","",B19*D19)
A20: =Ausruestung!B12 | B20: =Ausruestung!F12 | C20: =Ausruestung!E12 | E20: =IF(D20="","",B20*D20)
A21: =Ausruestung!B13 | B21: =Ausruestung!F13 | C21: =Ausruestung!E13 | E21: =IF(D21="","",B21*D21)
A22: =Ausruestung!B14 | B22: =Ausruestung!F14 | C22: =Ausruestung!E14 | E22: =IF(D22="","",B22*D22)
A23: =Ausruestung!B15 | B23: =Ausruestung!F15 | C23: =Ausruestung!E15 | E23: =IF(D23="","",B23*D23)
A24: =Ausruestung!B16 | B24: =Ausruestung!F16 | C24: =Ausruestung!E16 | E24: =IF(D24="","",B24*D24)
... A52: =Ausruestung!B44 | B52: =Ausruestung!F44 | C52: =Ausruestung!E44 | E52: =IF(D52="","",B52*D52)
A53: Gesamtkosten | E53: =SUM(E5:E52)

Sheet Lagerkontrolle
A1: Lagerkontrolle mit Ablaufdatum
A2: Haltbar-bis-Datum eintragen. Status: ok, bald prüfen (<= 90 Tage), ABGELAUFEN.
A4: Artikel | B4: Menge | C4: Einheit | D4: Kaufdatum | E4: Haltbar bis | F4: Verbleibend (Tage) | G4: Status
A5: Reis, Nudeln, Haferflocken | C5: kg | F5: =IF(E5="","",E5-TODAY()) | G5: =IF(E5="","",IF(F5<0,"ABGELAUFEN",IF(F5<=90,"bald prüfen","ok")))
A6: Hülsenfrüchte (Linsen, Bohnen) | C6: kg | F6: =IF(E6="","",E6-TODAY()) | G6: =IF(E6="","",IF(F6<0,"ABGELAUFEN",IF(F6<=90,"bald prüfen","ok")))
A7: Konserven (Gemüse, Fisch, Fleisch) | C7: kg | F7: =IF(E7="","",E7-TODAY()) | G7: =IF(E7="","",IF(F7<0,"ABGELAUFEN",IF(F7<=90,"bald prüfen","ok")))
A8: Speiseöl | C8: L | F8: =IF(E8="","",E8-TODAY()) | G8: =IF(E8="","",IF(F8<0,"ABGELAUFEN",IF(F8<=90,"bald prüfen","ok")))
A9: Zucker oder Honig | C9: kg | F9: =IF(E9="","",E9-TODAY()) | G9: =IF(E9="","",IF(F9<0,"ABGELAUFEN",IF(F9<=90,"bald prüfen","ok")))
A10: Nüsse, Müsli, Trockenfrüchte | C10: kg | F10: =IF(E10="","",E10-TODAY()) | G10: =IF(E10="","",IF(F10<0,"ABGELAUFEN",IF(F10<=90,"bald prüfen","ok")))
A11: H-Milch oder Milchpulver | C11: L | F11: =IF(E11="","",E11-TODAY()) | G11: =IF(E11="","",IF(F11<0,"ABGELAUFEN",IF(F11<=90,"bald prüfen","ok")))
A12: Knäckebrot oder Zwieback | C12: kg | F12: =IF(E12="","",E12-TODAY()) | G12: =IF(E12="","",IF(F12<0,"ABGELAUFEN",IF(F12<=90,"bald prüfen","ok")))
A13: Batterien AA | C13: Stück | F13: =IF(E13="","",E13-TODAY()) | G13: =IF(E13="","",IF(F13<0,"ABGELAUFEN",IF(F13<=90,"bald prüfen","ok")))
A14: Gaskartuschen | C14: Stück | F14: =IF(E14="","",E14-TODAY()) | G14: =IF(E14="","",IF(F14<0,"ABGELAUFEN",IF(F14<=90,"bald prüfen","ok")))
A15: Entkeimungstabletten | C15: Packung | F15: =IF(E15="","",E15-TODAY()) | G15: =IF(E15="","",IF(F15<0,"ABGELAUFEN",IF(F15<=90,"bald prüfen","ok")))
A16: Trockenbrennstoff-Würfel | C16: Stück | F16: =IF(E16="","",E16-TODAY()) | G16: =IF(E16="","",IF(F16<0,"ABGELAUFEN",IF(F16<=90,"bald prüfen","ok")))
A17: Medikamente (14 Tage Vorrat) | C17: Satz | F17: =IF(E17="","",E17-TODAY()) | G17: =IF(E17="","",IF(F17<0,"ABGELAUFEN",IF(F17<=90,"bald prüfen","ok")))

Sheet Wasservergleich
A1: Wasser pro Person und Tag (Liter)
A3: Maßstab | B3: Liter pro Tag
A4: BBK Trinkwasser (Trinken und Kochen) | B4: 2
A5: Körpergewicht 65 kg | B5: =65*Bedarf!B7/1000
A6: Körpergewicht 97,5 kg | B6: =97.5*Bedarf!B7/1000
A7: Körpergewicht 130 kg | B7: =130*Bedarf!B7/1000
A8: Sphere-Minimum (inkl. Hygiene) | B8: 15

Sheet Referenzen
A1: Quellen und Annahmen
A3: BBK: Ratgeber für Notfallvorsorge, Empfehlung 10 Tage Vorrat. Trinkwasser ca. 2 L pro Person und Tag.
A4: Sphere-Standard: Mindestwasser 15 L pro Person und Tag inkl. Hygiene, Mindest-Energie 2.100 kcal pro Tag.
A5: Annahme: Grundumsatz 24 kcal/kg/Tag, Krisen-Aktivität x1,3 (Bereich 1,2 bis 1,4).
A6: Annahme: Trinkwasser 35 ml/kg/Tag, Hygienewasser 2 L/Tag.
A7: Hinweis: Quellen wurden bei der Erstellung nicht online nachgeprüft. Vor dem Ausdruck bitte beim BBK prüfen.
